<?xml version="1.0" ?>
<robot name="Bobert" xmlns:xacro="http://www.ros.org/wiki/xacro">

<xacro:include filename="$(find Bobert_description)/urdf/materials.xacro" />
<xacro:include filename="$(find Bobert_description)/urdf/Bobert.ros2control" />
<xacro:include filename="$(find Bobert_description)/urdf/Bobert.gazebo" />
<link name="base_link">
  <inertial>
    <origin xyz="0.001616444348881833 -0.09751365978043731 0.11848829155889322" rpy="0 0 0"/>
    <mass value="40.76877140504577"/>
    <inertia ixx="0.370897" iyy="0.764615" izz="1.06958" ixy="-7.6e-05" iyz="-0.010092" ixz="2e-06"/>
  </inertial>
  <visual>
    <origin xyz="0 0 0" rpy="0 0 0"/>
    <geometry>
      <mesh filename="file://$(find Bobert_description)/meshes/base_link.stl" scale="0.001 0.001 0.001"/>
    </geometry>
    <material name="silver"/>
  </visual>
  <collision>
    <origin xyz="0 0 0" rpy="0 0 0"/>
    <geometry>
      <mesh filename="file://$(find Bobert_description)/meshes/base_link.stl" scale="0.001 0.001 0.001"/>
    </geometry>
  </collision>
</link>

<link name="wheel_left_1">
  <inertial>
    <origin xyz="0.026516397789354718 2.2139738049820057e-07 1.5630537235356012e-07" rpy="0 0 0"/>
    <mass value="7.63884245237393"/>
    <inertia ixx="0.021571" iyy="0.012513" izz="0.012513" ixy="0.0" iyz="0.0" ixz="-0.0"/>
  </inertial>
  <visual>
    <origin xyz="-0.140106 -0.071315 -0.080345" rpy="0 0 0"/>
    <geometry>
      <mesh filename="file://$(find Bobert_description)/meshes/wheel_left_1.stl" scale="0.001 0.001 0.001"/>
    </geometry>
    <material name="silver"/>
  </visual>
  <collision>
    <origin xyz="-0.140106 -0.071315 -0.080345" rpy="0 0 0"/>
    <geometry>
      <mesh filename="file://$(find Bobert_description)/meshes/wheel_left_1.stl" scale="0.001 0.001 0.001"/>
    </geometry>
  </collision>
</link>

<link name="wheel_rigth_1">
  <inertial>
    <origin xyz="-0.02651633470004558 1.1334412741703659e-07 2.1659195333090242e-07" rpy="0 0 0"/>
    <mass value="7.638838185872935"/>
    <inertia ixx="0.021571" iyy="0.012513" izz="0.012513" ixy="0.0" iyz="0.0" ixz="-0.0"/>
  </inertial>
  <visual>
    <origin xyz="0.136894 -0.071315 -0.080345" rpy="0 0 0"/>
    <geometry>
      <mesh filename="file://$(find Bobert_description)/meshes/wheel_rigth_1.stl" scale="0.001 0.001 0.001"/>
    </geometry>
    <material name="silver"/>
  </visual>
  <collision>
    <origin xyz="0.136894 -0.071315 -0.080345" rpy="0 0 0"/>
    <geometry>
      <mesh filename="file://$(find Bobert_description)/meshes/wheel_rigth_1.stl" scale="0.001 0.001 0.001"/>
    </geometry>
  </collision>
</link>

<link name="rotatori_suport_rigth_1">
  <inertial>
    <origin xyz="-0.0016060124775976597 -0.010448003356963081 -0.1757990893415789" rpy="0 0 0"/>
    <mass value="0.21087231289276429"/>
    <inertia ixx="9.6e-05" iyy="8e-05" izz="0.000112" ixy="-0.0" iyz="-2.7e-05" ixz="-0.0"/>
  </inertial>
  <visual>
    <origin xyz="0.111788 0.13187 -0.231706" rpy="0 0 0"/>
    <geometry>
      <mesh filename="file://$(find Bobert_description)/meshes/rotatori_suport_rigth_1.stl" scale="0.001 0.001 0.001"/>
    </geometry>
    <material name="silver"/>
  </visual>
  <collision>
    <origin xyz="0.111788 0.13187 -0.231706" rpy="0 0 0"/>
    <geometry>
      <mesh filename="file://$(find Bobert_description)/meshes/rotatori_suport_rigth_1.stl" scale="0.001 0.001 0.001"/>
    </geometry>
  </collision>
</link>

<link name="rotatori_suport_left_1">
  <inertial>
    <origin xyz="-0.0016060124775970491 -0.010448003356962998 -0.17579908934157884" rpy="0 0 0"/>
    <mass value="0.21087231289276429"/>
    <inertia ixx="9.6e-05" iyy="8e-05" izz="0.000112" ixy="-0.0" iyz="-2.7e-05" ixz="-0.0"/>
  </inertial>
  <visual>
    <origin xyz="-0.118212 0.13187 -0.231706" rpy="0 0 0"/>
    <geometry>
      <mesh filename="file://$(find Bobert_description)/meshes/rotatori_suport_left_1.stl" scale="0.001 0.001 0.001"/>
    </geometry>
    <material name="silver"/>
  </visual>
  <collision>
    <origin xyz="-0.118212 0.13187 -0.231706" rpy="0 0 0"/>
    <geometry>
      <mesh filename="file://$(find Bobert_description)/meshes/rotatori_suport_left_1.stl" scale="0.001 0.001 0.001"/>
    </geometry>
  </collision>
</link>

<link name="road_left_1">
  <inertial>
    <origin xyz="-0.15829771963284017 0.10574320309753191 -0.020646828759012834" rpy="0 0 0"/>
    <mass value="0.3614984125144465"/>
    <inertia ixx="0.000107" iyy="7.2e-05" izz="7.2e-05" ixy="0.0" iyz="0.0" ixz="0.0"/>
  </inertial>
  <visual>
    <origin xyz="-0.275041 0.264178 -0.0455" rpy="0 0 0"/>
    <geometry>
      <mesh filename="file://$(find Bobert_description)/meshes/road_left_1.stl" scale="0.001 0.001 0.001"/>
    </geometry>
    <material name="silver"/>
  </visual>
  <collision>
    <origin xyz="-0.275041 0.264178 -0.0455" rpy="0 0 0"/>
    <geometry>
      <mesh filename="file://$(find Bobert_description)/meshes/road_left_1.stl" scale="0.001 0.001 0.001"/>
    </geometry>
  </collision>
</link>

<link name="road_rigth_1">
  <inertial>
    <origin xyz="-0.15829771963284073 -0.12425679690246823 -0.02064682875901287" rpy="0 0 0"/>
    <mass value="0.3614984125144465"/>
    <inertia ixx="0.000107" iyy="7.2e-05" izz="7.2e-05" ixy="0.0" iyz="0.0" ixz="0.0"/>
  </inertial>
  <visual>
    <origin xyz="-0.045041 0.034178 -0.0455" rpy="0 0 0"/>
    <geometry>
      <mesh filename="file://$(find Bobert_description)/meshes/road_rigth_1.stl" scale="0.001 0.001 0.001"/>
    </geometry>
    <material name="silver"/>
  </visual>
  <collision>
    <origin xyz="-0.045041 0.034178 -0.0455" rpy="0 0 0"/>
    <geometry>
      <mesh filename="file://$(find Bobert_description)/meshes/road_rigth_1.stl" scale="0.001 0.001 0.001"/>
    </geometry>
  </collision>
</link>

<joint name="Revolution 3" type="continuous">
  <origin xyz="0.140106 0.071315 0.080345" rpy="0 0 0"/>
  <parent link="base_link"/>
  <child link="wheel_left_1"/>
  <axis xyz="1.0 0.0 0.0"/>
</joint>

<joint name="Revolution  4" type="continuous">
  <origin xyz="-0.136894 0.071315 0.080345" rpy="0 0 0"/>
  <parent link="base_link"/>
  <child link="wheel_rigth_1"/>
  <axis xyz="-1.0 -0.0 0.0"/>
</joint>

<joint name="Revolution  5" type="continuous">
  <origin xyz="-0.111788 -0.13187 0.231706" rpy="0 0 0"/>
  <parent link="base_link"/>
  <child link="rotatori_suport_rigth_1"/>
  <axis xyz="-0.0 0.0 -1.0"/>
</joint>

<joint name="Revolution 6" type="continuous">
  <origin xyz="0.118212 -0.13187 0.231706" rpy="0 0 0"/>
  <parent link="base_link"/>
  <child link="rotatori_suport_left_1"/>
  <axis xyz="-0.0 0.0 -1.0"/>
</joint>

<joint name="Revolution  7" type="continuous">
  <origin xyz="0.156829 -0.132308 -0.186206" rpy="0 0 0"/>
  <parent link="rotatori_suport_left_1"/>
  <child link="road_left_1"/>
  <axis xyz="-1.0 -0.0 0.0"/>
</joint>

<joint name="Revolution  8" type="continuous">
  <origin xyz="0.156829 0.097692 -0.186206" rpy="0 0 0"/>
  <parent link="rotatori_suport_rigth_1"/>
  <child link="road_rigth_1"/>
  <axis xyz="-1.0 -0.0 0.0"/>
</joint>

</robot>
